promise1.catch((err) => {
  console.log(err);
});